
29-05-2020 13-37-01: Starting game vs AdditionalPylons
C:\Users\Manuel\AppData\Local\Programs\Python\Python37-32\lib\importlib\_bootstrap.py:219: RuntimeWarning: numpy.ufunc size changed, may indicate binary incompatibility. Expected 112 from C header, got 124 from PyObject
  return f(*args, **kwds)
C:\Users\Manuel\AppData\Local\Programs\Python\Python37-32\lib\importlib\_bootstrap.py:219: RuntimeWarning: numpy.ufunc size changed, may indicate binary incompatibility. Expected 112 from C header, got 124 from PyObject
  return f(*args, **kwds)
C:\Users\Manuel\AppData\Local\Programs\Python\Python37-32\lib\importlib\_bootstrap.py:219: RuntimeWarning: numpy.ufunc size changed, may indicate binary incompatibility. Expected 112 from C header, got 124 from PyObject
  return f(*args, **kwds)
C:\Users\Manuel\Desktop\Ladder\Bots\MavBot\__init__.py:85: RuntimeWarning: coroutine 'ClientWebSocketResponse.close' was never awaited
  ws_connection.close()
RuntimeWarning: Enable tracemalloc to get the object allocation traceback
C:\Users\Manuel\AppData\Roaming\Python\Python37\site-packages\aiohttp\client.py:309: ResourceWarning: Unclosed client session <aiohttp.client.ClientSession object at 0x0B138E30>

29-05-2020 18-16-40: Starting game vs WorkerRushBot
C:\Users\Manuel\AppData\Local\Programs\Python\Python37-32\lib\importlib\_bootstrap.py:219: RuntimeWarning: numpy.ufunc size changed, may indicate binary incompatibility. Expected 112 from C header, got 124 from PyObject
  return f(*args, **kwds)
C:\Users\Manuel\AppData\Local\Programs\Python\Python37-32\lib\importlib\_bootstrap.py:219: RuntimeWarning: numpy.ufunc size changed, may indicate binary incompatibility. Expected 112 from C header, got 124 from PyObject
  return f(*args, **kwds)
C:\Users\Manuel\AppData\Local\Programs\Python\Python37-32\lib\importlib\_bootstrap.py:219: RuntimeWarning: numpy.ufunc size changed, may indicate binary incompatibility. Expected 112 from C header, got 124 from PyObject
  return f(*args, **kwds)
C:\Users\Manuel\Desktop\Ladder\Bots\MavBot\__init__.py:85: RuntimeWarning: coroutine 'ClientWebSocketResponse.close' was never awaited
  ws_connection.close()
RuntimeWarning: Enable tracemalloc to get the object allocation traceback
C:\Users\Manuel\AppData\Roaming\Python\Python37\site-packages\aiohttp\client.py:309: ResourceWarning: Unclosed client session <aiohttp.client.ClientSession object at 0x031C7090>

29-05-2020 18-19-29: Starting game vs WorkerRushBot
C:\Users\Manuel\AppData\Local\Programs\Python\Python37-32\lib\importlib\_bootstrap.py:219: RuntimeWarning: numpy.ufunc size changed, may indicate binary incompatibility. Expected 112 from C header, got 124 from PyObject
  return f(*args, **kwds)
C:\Users\Manuel\AppData\Local\Programs\Python\Python37-32\lib\importlib\_bootstrap.py:219: RuntimeWarning: numpy.ufunc size changed, may indicate binary incompatibility. Expected 112 from C header, got 124 from PyObject
  return f(*args, **kwds)
C:\Users\Manuel\AppData\Local\Programs\Python\Python37-32\lib\importlib\_bootstrap.py:219: RuntimeWarning: numpy.ufunc size changed, may indicate binary incompatibility. Expected 112 from C header, got 124 from PyObject
  return f(*args, **kwds)
C:\Users\Manuel\Desktop\Ladder\Bots\MavBot\__init__.py:85: RuntimeWarning: coroutine 'ClientWebSocketResponse.close' was never awaited
  ws_connection.close()
RuntimeWarning: Enable tracemalloc to get the object allocation traceback
C:\Users\Manuel\AppData\Roaming\Python\Python37\site-packages\aiohttp\client.py:309: ResourceWarning: Unclosed client session <aiohttp.client.ClientSession object at 0x0B45AE10>

29-05-2020 18-21-16: Starting game vs WorkerRushBot
C:\Users\Manuel\AppData\Local\Programs\Python\Python37-32\lib\importlib\_bootstrap.py:219: RuntimeWarning: numpy.ufunc size changed, may indicate binary incompatibility. Expected 112 from C header, got 124 from PyObject
  return f(*args, **kwds)
C:\Users\Manuel\AppData\Local\Programs\Python\Python37-32\lib\importlib\_bootstrap.py:219: RuntimeWarning: numpy.ufunc size changed, may indicate binary incompatibility. Expected 112 from C header, got 124 from PyObject
  return f(*args, **kwds)
C:\Users\Manuel\AppData\Local\Programs\Python\Python37-32\lib\importlib\_bootstrap.py:219: RuntimeWarning: numpy.ufunc size changed, may indicate binary incompatibility. Expected 112 from C header, got 124 from PyObject
  return f(*args, **kwds)
C:\Users\Manuel\AppData\Roaming\Python\Python37\site-packages\aiohttp\client.py:309: ResourceWarning: Unclosed client session <aiohttp.client.ClientSession object at 0x0B529E50>
  **kwargs)
ResourceWarning: Enable tracemalloc to get the object allocation traceback
C:\Users\Manuel\Desktop\Ladder\Bots\MavBot\__init__.py:85: RuntimeWarning: coroutine 'ClientWebSocketResponse.close' was never awaited
  ws_connection.close()
RuntimeWarning: Enable tracemalloc to get the object allocation traceback
Traceback (most recent call last):
  File "C:\Users\Manuel\Desktop\Ladder\Bots\MavBot\sc2\protocol.py", line 43, in __request
    response_bytes = await self._ws.receive_bytes()
  File "C:\Users\Manuel\AppData\Roaming\Python\Python37\site-packages\aiohttp\client_ws.py", line 283, in receive_bytes
    msg.data))
TypeError: Received message 257:None is not bytes

During handling of the above exception, another exception occurred:

Traceback (most recent call last):
  File "C:\Users\Manuel\Desktop\Ladder\Bots\MavBot\__init__.py", line 76, in join_ladder_game
    result = await sc2.main._play_game(players[0], client, realtime, portconfig, step_time_limit, game_time_limit)
  File "C:\Users\Manuel\Desktop\Ladder\Bots\MavBot\sc2\main.py", line 246, in _play_game
    result = await _play_game_ai(client, player_id, player.ai, realtime, step_time_limit, game_time_limit)
  File "C:\Users\Manuel\Desktop\Ladder\Bots\MavBot\sc2\main.py", line 228, in _play_game_ai
    await client.step()
  File "C:\Users\Manuel\Desktop\Ladder\Bots\MavBot\sc2\client.py", line 141, in step
    return await self._execute(step=sc_pb.RequestStep(count=self.game_step))
  File "C:\Users\Manuel\Desktop\Ladder\Bots\MavBot\sc2\protocol.py", line 67, in _execute
    response = await self.__request(request)
  File "C:\Users\Manuel\Desktop\Ladder\Bots\MavBot\sc2\protocol.py", line 48, in __request
    sys.exit(2)
SystemExit: 2

During handling of the above exception, another exception occurred:

Traceback (most recent call last):
  File "run.py", line 15, in <module>
    result, opponentid = run_ladder_game(bot)
  File "C:\Users\Manuel\Desktop\Ladder\Bots\MavBot\__init__.py", line 67, in run_ladder_game
    result = asyncio.get_event_loop().run_until_complete(g)
  File "C:\Users\Manuel\AppData\Local\Programs\Python\Python37-32\lib\asyncio\base_events.py", line 584, in run_until_complete
    return future.result()
  File "C:\Users\Manuel\Desktop\Ladder\Bots\MavBot\__init__.py", line 81, in join_ladder_game
    except ConnectionAlreadyClosed:
NameError: name 'ConnectionAlreadyClosed' is not defined

29-05-2020 18-23-20: Starting game vs WorkerRushBot
C:\Users\Manuel\AppData\Local\Programs\Python\Python37-32\lib\importlib\_bootstrap.py:219: RuntimeWarning: numpy.ufunc size changed, may indicate binary incompatibility. Expected 112 from C header, got 124 from PyObject
  return f(*args, **kwds)
C:\Users\Manuel\AppData\Local\Programs\Python\Python37-32\lib\importlib\_bootstrap.py:219: RuntimeWarning: numpy.ufunc size changed, may indicate binary incompatibility. Expected 112 from C header, got 124 from PyObject
  return f(*args, **kwds)
C:\Users\Manuel\AppData\Local\Programs\Python\Python37-32\lib\importlib\_bootstrap.py:219: RuntimeWarning: numpy.ufunc size changed, may indicate binary incompatibility. Expected 112 from C header, got 124 from PyObject
  return f(*args, **kwds)
C:\Users\Manuel\AppData\Roaming\Python\Python37\site-packages\aiohttp\client.py:309: ResourceWarning: Unclosed client session <aiohttp.client.ClientSession object at 0x0B469E30>
  **kwargs)
ResourceWarning: Enable tracemalloc to get the object allocation traceback
C:\Users\Manuel\Desktop\Ladder\Bots\MavBot\__init__.py:85: RuntimeWarning: coroutine 'ClientWebSocketResponse.close' was never awaited
  ws_connection.close()
RuntimeWarning: Enable tracemalloc to get the object allocation traceback
Traceback (most recent call last):
  File "C:\Users\Manuel\Desktop\Ladder\Bots\MavBot\sc2\protocol.py", line 43, in __request
    response_bytes = await self._ws.receive_bytes()
  File "C:\Users\Manuel\AppData\Roaming\Python\Python37\site-packages\aiohttp\client_ws.py", line 283, in receive_bytes
    msg.data))
TypeError: Received message 257:None is not bytes

During handling of the above exception, another exception occurred:

Traceback (most recent call last):
  File "C:\Users\Manuel\Desktop\Ladder\Bots\MavBot\__init__.py", line 76, in join_ladder_game
    result = await sc2.main._play_game(players[0], client, realtime, portconfig, step_time_limit, game_time_limit)
  File "C:\Users\Manuel\Desktop\Ladder\Bots\MavBot\sc2\main.py", line 246, in _play_game
    result = await _play_game_ai(client, player_id, player.ai, realtime, step_time_limit, game_time_limit)
  File "C:\Users\Manuel\Desktop\Ladder\Bots\MavBot\sc2\main.py", line 228, in _play_game_ai
    await client.step()
  File "C:\Users\Manuel\Desktop\Ladder\Bots\MavBot\sc2\client.py", line 141, in step
    return await self._execute(step=sc_pb.RequestStep(count=self.game_step))
  File "C:\Users\Manuel\Desktop\Ladder\Bots\MavBot\sc2\protocol.py", line 67, in _execute
    response = await self.__request(request)
  File "C:\Users\Manuel\Desktop\Ladder\Bots\MavBot\sc2\protocol.py", line 48, in __request
    sys.exit(2)
SystemExit: 2

During handling of the above exception, another exception occurred:

Traceback (most recent call last):
  File "run.py", line 15, in <module>
    result, opponentid = run_ladder_game(bot)
  File "C:\Users\Manuel\Desktop\Ladder\Bots\MavBot\__init__.py", line 67, in run_ladder_game
    result = asyncio.get_event_loop().run_until_complete(g)
  File "C:\Users\Manuel\AppData\Local\Programs\Python\Python37-32\lib\asyncio\base_events.py", line 584, in run_until_complete
    return future.result()
  File "C:\Users\Manuel\Desktop\Ladder\Bots\MavBot\__init__.py", line 81, in join_ladder_game
    except ConnectionAlreadyClosed:
NameError: name 'ConnectionAlreadyClosed' is not defined
